[2024-05-24T08:35:32.715+0000] {local_task_job_runner.py:120} INFO - ::group::Pre task execution logs
[2024-05-24T08:35:32.729+0000] {taskinstance.py:2076} INFO - Dependencies all met for dep_context=non-requeueable deps ti=<TaskInstance: our_first_dag_v2.second_task scheduled__2024-05-23T00:00:00+00:00 [queued]>
[2024-05-24T08:35:32.732+0000] {taskinstance.py:2076} INFO - Dependencies all met for dep_context=requeueable deps ti=<TaskInstance: our_first_dag_v2.second_task scheduled__2024-05-23T00:00:00+00:00 [queued]>
[2024-05-24T08:35:32.733+0000] {taskinstance.py:2306} INFO - Starting attempt 2 of 6
[2024-05-24T08:35:32.738+0000] {taskinstance.py:2330} INFO - Executing <Task(BashOperator): second_task> on 2024-05-23 00:00:00+00:00
[2024-05-24T08:35:32.742+0000] {logging_mixin.py:188} WARNING - /home/***/.local/lib/python3.12/site-packages/***/task/task_runner/standard_task_runner.py:61 DeprecationWarning: This process (pid=1424) is multi-threaded, use of fork() may lead to deadlocks in the child.
[2024-05-24T08:35:32.744+0000] {standard_task_runner.py:63} INFO - Started process 1429 to run task
[2024-05-24T08:35:32.743+0000] {standard_task_runner.py:90} INFO - Running: ['***', 'tasks', 'run', 'our_first_dag_v2', 'second_task', 'scheduled__2024-05-23T00:00:00+00:00', '--job-id', '43', '--raw', '--subdir', 'DAGS_FOLDER/our_first_dag.py', '--cfg-path', '/tmp/tmp25_ujh3y']
[2024-05-24T08:35:32.744+0000] {standard_task_runner.py:91} INFO - Job 43: Subtask second_task
[2024-05-24T08:35:32.765+0000] {task_command.py:426} INFO - Running <TaskInstance: our_first_dag_v2.second_task scheduled__2024-05-23T00:00:00+00:00 [running]> on host 6bbd6353fbe6
[2024-05-24T08:35:32.800+0000] {taskinstance.py:2648} INFO - Exporting env vars: AIRFLOW_CTX_DAG_OWNER='gauti' AIRFLOW_CTX_DAG_ID='our_first_dag_v2' AIRFLOW_CTX_TASK_ID='second_task' AIRFLOW_CTX_EXECUTION_DATE='2024-05-23T00:00:00+00:00' AIRFLOW_CTX_TRY_NUMBER='2' AIRFLOW_CTX_DAG_RUN_ID='scheduled__2024-05-23T00:00:00+00:00'
[2024-05-24T08:35:32.801+0000] {taskinstance.py:430} INFO - ::endgroup::
[2024-05-24T08:35:32.807+0000] {subprocess.py:63} INFO - Tmp dir root location: /tmp
[2024-05-24T08:35:32.808+0000] {subprocess.py:75} INFO - Running command: ['/usr/bin/bash', '-c', 'echo hai, I am newly created task 2 and I will run after the first task!:)']
[2024-05-24T08:35:32.811+0000] {subprocess.py:86} INFO - Output:
[2024-05-24T08:35:32.812+0000] {subprocess.py:93} INFO - /usr/bin/bash: -c: line 1: syntax error near unexpected token `)'
[2024-05-24T08:35:32.812+0000] {subprocess.py:93} INFO - /usr/bin/bash: -c: line 1: `echo hai, I am newly created task 2 and I will run after the first task!:)'
[2024-05-24T08:35:32.812+0000] {subprocess.py:97} INFO - Command exited with return code 2
[2024-05-24T08:35:32.813+0000] {taskinstance.py:441} INFO - ::group::Post task execution logs
[2024-05-24T08:35:32.817+0000] {taskinstance.py:2905} ERROR - Task failed with exception
Traceback (most recent call last):
  File "/home/airflow/.local/lib/python3.12/site-packages/airflow/models/taskinstance.py", line 465, in _execute_task
    result = _execute_callable(context=context, **execute_callable_kwargs)
             ^^^^^^^^^^^^^^^^^^^^^^^^^^^^^^^^^^^^^^^^^^^^^^^^^^^^^^^^^^^^^
  File "/home/airflow/.local/lib/python3.12/site-packages/airflow/models/taskinstance.py", line 432, in _execute_callable
    return execute_callable(context=context, **execute_callable_kwargs)
           ^^^^^^^^^^^^^^^^^^^^^^^^^^^^^^^^^^^^^^^^^^^^^^^^^^^^^^^^^^^^
  File "/home/airflow/.local/lib/python3.12/site-packages/airflow/models/baseoperator.py", line 400, in wrapper
    return func(self, *args, **kwargs)
           ^^^^^^^^^^^^^^^^^^^^^^^^^^^
  File "/home/airflow/.local/lib/python3.12/site-packages/airflow/operators/bash.py", line 243, in execute
    raise AirflowException(
airflow.exceptions.AirflowException: Bash command failed. The command returned a non-zero exit code 2.
[2024-05-24T08:35:32.819+0000] {taskinstance.py:1206} INFO - Marking task as UP_FOR_RETRY. dag_id=our_first_dag_v2, task_id=second_task, run_id=scheduled__2024-05-23T00:00:00+00:00, execution_date=20240523T000000, start_date=20240524T083532, end_date=20240524T083532
[2024-05-24T08:35:32.825+0000] {standard_task_runner.py:110} ERROR - Failed to execute job 43 for task second_task (Bash command failed. The command returned a non-zero exit code 2.; 1429)
[2024-05-24T08:35:32.843+0000] {local_task_job_runner.py:240} INFO - Task exited with return code 1
[2024-05-24T08:35:32.850+0000] {taskinstance.py:3498} INFO - 0 downstream tasks scheduled from follow-on schedule check
[2024-05-24T08:35:32.851+0000] {local_task_job_runner.py:222} INFO - ::endgroup::
