[2024-05-25T14:07:46.178+0000] {task_context_logger.py:104} ERROR - Executor reports task instance <TaskInstance: dag_python_operator_v04.greet scheduled__2024-05-23T00:00:00+00:00 [queued]> finished (success) although the task says it's queued. (Info: None) Was the task killed externally?
